Workbook
Name Leeftijd: Vakantie!$D$2:$D$9
Name Account: CRM!$A$2:$A$546
Name CRM: CRM!$A$2:$O$546
Name Schalen25: Schalen25!$A$4:$I$61
Name Mins: Vakantie!$B$2:$B$9
Name Vakantie: Vakantie!$A$2:$E$9

Sheet Form
C1: =FillIn!H4 -> DeNeX Uitzendbureau B.V.
C2: New Employee Application Form
C4: Salutation | E4: =IF(D4="dhr.","de heer","mevrouw") -> mevrouw | G4: Bank account | I4: =UPPER(H4)
C6: Initials | E6: =UPPER(SUBSTITUTE(SUBSTITUTE(SUBSTITUTE(MID(SUBSTITUTE(D6,".",""),1,1)&"."&MID(SUBSTITUTE(D6,".",""),2,1)&"."&MID(SUBSTITUTE(D6,".",""),3,1)&"."&MID(SUBSTITUTE(D6,".",""),4,1)&".","....","."),"...","."),"..",".")) -> . | G6: Date of birth
C8: Last Name | E8: =D4&" "&E6&" "&PROPER(D8) -> . | G8: Employment date | I8: =PROPER(D8)
C10: Address/Street | E10: =IF(J10="month",H10,IF(J10="year",H10*12,ROUND(H10/4,2))) | F10: =E10&" maanden" -> maanden | G10: Contract duration | I10: =PROPER(D10) | J10: month | O10: =E10
O11: =E11
C12: Postal Code/City | E12: =IF(J12="month",H12,IF(J12="year",H12*12,ROUND(H12/4,2))) -> 1 | G12: Probationary period | H12: 1 | I12: =IF(E12>1,E12&" maanden"," maand") -> maand | J12: month | O12: =E12 -> 1
C14: Country | E14: =EDATE(H8,H10)-1 -> -1 | F14: =UPPER(IF(LEFT(D14,1)="b","Bulgarije",IF(LEFT(D14,1)="n","Nederland",D14))) | G14: Hourly wage | H14: D5
C16: Telephone | E16: =H16&" uur "&J16 -> 40 uur per week | G16: Working hours | H16: 40 | I16: uur | J16: per week
C18: Email | G18: Position | H18: Driver | I18: =PROPER(H18) -> Driver | M18: =E18
C20: KIWA | M20: =E20
C22: BSN | M22: =E22
C26: New ZZP Application Form
C28: Salutation | E28: =IF(D28="dhr.","de heer","mevrouw") -> mevrouw
C30: Initials | E30: =UPPER(SUBSTITUTE(SUBSTITUTE(SUBSTITUTE(MID(SUBSTITUTE(D30,".",""),1,1)&"."&MID(SUBSTITUTE(D30,".",""),2,1)&"."&MID(SUBSTITUTE(D30,".",""),3,1)&"."&MID(SUBSTITUTE(D30,".",""),4,1)&".","....","."),"...","."),"..",".")) -> .
C32: Last Name | E32: =D28&" "&E30&" "&PROPER(D32) -> .
C34: Address/Street | E34: =IF(F57="month",D57,IF(F57="year",D57*12,ROUND(D57/4,2))) | F34: =E34&" maanden" -> maanden
C36: Postal Code/City | E36: =IF(F59="month",D59,IF(F59="year",D59*12,ROUND(D59/4,2))) -> 1
C38: Country | E38: =EDATE(D55,D57)-1 -> -1 | F38: =UPPER(IF(LEFT(D38,1)="b","Bulgarije",IF(LEFT(D38,1)="n","Nederland",D38)))
C40: Telephone | E40: =D63&" uur "&F63 -> 40 uur per week
C42: Email
C44: KvK Number
C46: BSN
C49: Merge Driver, Truck, Client
C51: Bank account | E51: =UPPER(D51)
C53: Date of birth
C55: Employment date | E55: =PROPER(D32)
C57: Contract duration | E57: =PROPER(D34) | F57: month
C59: Probationary period | D59: 1 | E59: =IF(E36>1,E36&" maanden"," maand") -> maand | F59: month
C61: Hourly wage
C63: Working hours | D63: 40 | E63: uur | F63: per week
C65: Position | D65: Driver | E65: =PROPER(D65) -> Driver

Sheet FillIn
A1: Inhoud
C2: De ondertekende:
C3: Krachten: | D3: =VLOOKUP($D$4,Employee!$A$3:$T$37,1,false) -> dhr. G. Aslan | G3: Werkgever: | H3: DeNeX Uitzendbureau B.V. | M3: =IF(VLOOKUP($D$4,Employee!$A$3:$T$37,2,false)="de heer","heer","mevrouw") -> heer | N3: =VLOOKUP($D$4,Employee!$A$3:$T$37,3,false)&" "&VLOOKUP($D$4,Employee!$A$3:$T$37,4,false) -> G. Aslan
C4: Naam: | D4: dhr. G. Aslan | G4: Bedrijfsnaam: | H4: =VLOOKUP($H$3,CRM,1,TRUE) -> DeNeX Uitzendbureau B.V. | M4: =VLOOKUP($D$4,Employee!$A$3:$T$37,2,false)&" "&VLOOKUP($D$4,Employee!$A$3:$T$37,3,false)&" "&VLOOKUP($D$4,Employee!$A$3:$T$37,4,false) -> de heer G. Aslan | O4: =VLOOKUP($D$4,Employee!$A$3:$T$37,4,false)&", "&VLOOKUP($D$4,Employee!$A$3:$T$37,3,false) -> Aslan, G.
C5: Adres: | D5: =VLOOKUP($D$4,Employee!$A$3:$T$37,5,false) -> Bikscotelaan 248 /2/2140 Borgerhout | G5: Naam: | H5: =VLOOKUP($H$3,CRM,13,TRUE)&" "&VLOOKUP($H$3,CRM,3,TRUE)&" "&VLOOKUP($H$3,CRM,15,TRUE) -> Hr. D.O. Ibryam | M5: =IF(VLOOKUP($H$3,CRM,13,TRUE)="Mw.","mevrouw ","de heer ")&VLOOKUP($H$3,CRM,3,TRUE)&" "&VLOOKUP($H$3,CRM,15,TRUE) -> de heer D.O. Ibryam | N5: =IF(VLOOKUP($H$3,CRM,13,TRUE)="Mw.","mevrouw ","heer ")&VLOOKUP($H$3,CRM,3,TRUE)&" "&VLOOKUP($H$3,CRM,15,TRUE) -> heer D.O. Ibryam
C6: Postcode: | D6: =LEFT(VLOOKUP($D$4,Employee!$A$3:$T$37,6,false),7) -> 2140 An | G6: Adres: | H6: =VLOOKUP($H$3,CRM,6,TRUE) -> Gebroken Meeldijk 66, Unit 1.15
C7: Plaats: | D7: =TRIM(MID(VLOOKUP($D$4,Employee!$A$3:$T$37,6,FALSE),8,LEN(VLOOKUP($D$4,Employee!$A$3:$T$37,6,FALSE)))) -> twerp | G7: Postcode: | H7: =VLOOKUP($H$3,CRM,8,TRUE) -> 2991 VD
C8: Geb.datum: | D8: =VLOOKUP($D$4,Employee!$A$3:$T$37,13,false) -> 29310 | G8: Plaats: | H8: =VLOOKUP($H$3,CRM,7,TRUE) -> Barendrecht
C9: BSN: | D9: =VLOOKUP($D$4,Employee!$A$3:$T$37,11,false) -> 235116026 | G9: Telefoon: | H9: =VLOOKUP($H$3,CRM,9,TRUE) -> +31628813127 | M9: =VLOOKUP($H$3,CRM,11,TRUE) -> NL
G10: BTW Nummer: | H10: =VLOOKUP($H$3,CRM,12,TRUE) -> NL863179344B01
C11: In dienst van | D11: =VLOOKUP($D$4,Employee!$A$3:$T$37,14,false) -> 45979 | G11: KvK Nummer: | H11: =VLOOKUP($H$3,CRM,10,TRUE) -> 84349735
C12: Dienst tot | D12: =VLOOKUP($D$4,Employee!$A$3:$T$37,16,false) -> 46159
C13: Functie | D13: =VLOOKUP($D$4,Employee!$A$3:$T$37,20,false) -> Chauffeur
C14: Proeftijd | D14: =VLOOKUP($D$4,Employee!$A$3:$T$37,17,false) | F14: =EDATE(D11,VALUE(LEFT(D14,2))) -> 45979 | G14: Transportmanager: | H14: Intern
C15: Arbeidsduur | D15: =VLOOKUP($D$4,Employee!$A$3:$T$37,19,false) -> 40 uur per week | G15: Aantal voertuig(en) | H15: 6
C16: Weekplanning | D16: maandag t/m vrijdag | G16: Uur per week: | H16: 40
C17: Werktijden | D17: tussen 7:00 uur t/m 19:00 uur
C18: Opzegtermijn: | D18: 1 maand
C19: Vergoeding: | D19: 350 | E19: per mnd | G19: Vergoeding incl. BTW: | H19: 423.5 | I19: per mnd
C21: Loonschaal | D21: =VLOOKUP($G$21,Schalen25,2,TRUE) -> D | G21: D 5
C22: Trede | D22: =VLOOKUP($G$21,Schalen25,3,TRUE) -> 5 | G22: Weekloon: | H22: =VLOOKUP($G$21,Schalen25,4,TRUE) -> 748.58
C23: Uurloon 100% | D23: =VLOOKUP($G$21,Schalen25,7,TRUE) -> 18.71 | G23: Loon 4 weken: | H23: =VLOOKUP($G$21,Schalen25,5,TRUE) -> 2994.32
C24: Afwijkende loon: | D24: =D23 -> 18.71
C25: Reiskosten | D25: 0.23 | G25: Loon maand: | H25: =VLOOKUP($G$21,Schalen25,6,TRUE) -> 3254.83
C26: Max.reiskosten | D26: 100 | G26: Uurloon 130% | H26: =VLOOKUP($G$21,Schalen25,8,TRUE) -> 24.32
G27: Uurloon 150% | H27: =VLOOKUP($G$21,Schalen25,9,TRUE) -> 28.07
C28: Plaats | D28: Rijswijk
C29: Datum | D29: =D11-1 -> 45978
G30: Leeftijd: | H30: =YEAR(NOW())-YEAR(D8) -> 45 | I30: =LOOKUP($H$30,Mins,Vakantie!A2:A9) -> 5
C31: CAO (niet in te vullen) | G31: 39 | H31: 3
C32: Vakantie leeftijd | D32: =LOOKUP(H30,Mins,Leeftijd) -> 45 t/m 49 jaar | G32: 19 t/m 39 jaar | H32: 19 t/m 39 jaar | M32: =LOOKUP(H30,Mins,Vakantie!A2:A9) -> 5
C33: Vacantiedagen | D33: =VLOOKUP(I30,Vakantie,5,true) -> 25 dagen | G33: Onbetaald verlof:
C34: ATV | D34: 3.5 | G34: Aantal dagen: | H34: =NETWORKDAYS(H36,H37) -> 129
C35: Vakantiebijslag | D35: 0.08 | G35: Dagen/Uren: | H35: dagen
G36: Begin datum: | H36: 45979 | M36: =DATEDIF(D11, D29, "M") -> #NUM!
C37: Annex | G37: Eind datum: | H37: 46159
C38: Datum: | D38: 45963
C39: functiewijziging: | G39: Uitzendkracht:
C40: Functie en Schaal: | G40: Contractduur: | H40: =VLOOKUP($D$4,Employee!A3:O37,15,false) -> 6 maanden | I40: 7
C41: Arbeidsduur: | G41: Einddatum: | H41: =EDATE(D11-1,I40) -> 46190
...

Sheet Employee
A2: Name | B2: Salutation | C2: Initials | D2: Last Name | E2: Address/Street | F2: Postal Code/City | G2: Country | H2: Telephone | I2: Email | J2: KIWA | K2: BSN | L2: Bank account | M2: Date of birth | N2: Employment date | O2: Contract duration | P2: ContractEndDate | Q2: Probationary period | R2: Hourly wage | S2: Working hours | T2: Position
A3: dhr. G. Boeru | B3: de heer | C3: G. | D3: Boeru | E3: Str.Lanternie Nr.92 | F3: 023095 Bucuresti | G3: ROMANIA | H3: 31616032687 | I3: boerugabi@yahoo.com | J3: 45964 | K3: 447266925 | L3: NL54INGB0105640972 | M3: 27324 | N3: 45964 | O3: 6 maanden | P3: 46144 | R3: 18.71 | S3: 40 uur per week | T3: Chauffeur
A4: dhr. R. Tataru | B4: de heer | C4: R. | D4: Tataru | E4: Str.Grainitei Nr.27 Bl.S2 Sc.B Ap.2 | F4: 705200 Pascani | G4: ROMANIA | H4: 40756724384 | I4: rabert_tataru88@yahoo.com | J4: 45964 | K4: 292515121 | M4: 32206 | N4: 45964 | O4: 6 maanden | P4: 46144 | R4: 18.71 | S4: 40 uur per week | T4: Chauffeur
A5: dhr. I. Gyurov | B5: de heer | C5: I. | D5: Gyurov | E5: Str.Blagoy Gebrev 58/43 | G5: BULGARIJE | H5: 359899705392 | I5: Ivan.v.gyurov@gmail.com | M5: 30033 | N5: 45964 | O5: 6 maanden | P5: 46144 | R5: 18.71 | S5: 40 uur per week | T5: Chauffeur
A6: dhr. R. Stiac | B6: de heer | C6: R. | D6: Stiac | E6: Ale.Trandafirilor,2A Bl.1 Sc.B,Et.5,Ap.503 Oradea | G6: ROMANIA | H6: 0040 775 309 576 | I6: razvanstiac@yahoo.com | J6: 45966 | K6: 424099536 | L6: RO44BRDE0505V1117399050 | M6: 30283 | N6: 45966 | O6: 6 maanden | P6: 46177 | R6: 18.71 | S6: 40 uur per week | T6: Chauffeur
A7: dhr. D.I. Bejan | B7: de heer | C7: D.I. | D7: Bejan | E7: Sat.Stroiesti | F7: 717226 Botasani | G7: ROMANIA | H7: 31623057192 | I7: bejan.olani20@gmail.com | J7: 45971 | K7: 336659520 | L7: NL64INGB0102322422 | M7: 34413 | N7: 45971 | O7: 6 maanden | P7: 46152 | R7: 18.71 | S7: 40 uur per week | T7: Chauffeur
A8: dhr. G. Aslan | B8: de heer | C8: G. | D8: Aslan | E8: Bikscotelaan 248 /2/2140 Borgerhout | F8: 2140 Antwerp | G8: BELGIUM | H8: 0032 483120970 | I8: gorkanaslan@hotmail.com | J8: 45979 | K8: 235116026 | L8: BE58143105213779 | M8: 29310 | N8: 45979 | O8: 6 maanden | P8: 46159 | R8: 18.71 | S8: 40 uur per week | T8: Chauffeur

Sheet ZZP
B1: OVEREENKOMST VAN OPDRACHT
B3: De ondergetekenden:
B4: Opdrachtgever: | F4: Opdrachtnemer:
B5: Bedrijfsnaam | C5: : | D5: =FillIn!H4 -> DeNeX Uitzendbureau B.V. | F5: Bedrijfsnaam | G5: : | H5: =FillIn!G47 -> A.A. Kazakov
B6: Adres | C6: : | D6: =FillIn!H6 -> Gebroken Meeldijk 66, Unit 1.15 | F6: Adres | G6: : | H6: =FillIn!H48 -> Loosduinseweg 867
B7: Postcode/Plaats | C7: : | D7: =FillIn!H7&" "&FillIn!H8 -> 2991 VD Barendrecht | F7: Postcode/Plaats | G7: : | H7: =FillIn!H49&" "&FillIn!I49 -> 2571AV s-Gravenhage
B8: Contact | C8: : | D8: =FillIn!M5 -> de heer D.O. Ibryam | F8: Contact | G8: : | H8: =FillIn!M50 -> deheer A.A. Kazakov
B10: OVERWEGENDE DAT:
B12: de Opdrachtnemer door de Opdrachtgever is benaderd om de nader te noemen werkzaamheden te verrichten, en de Opdrachtnemer in staat en bereid is deze werkzaamheden te verrichten;
B14: de Partijen overeen zijn gekomen zich uitsluitend te verbinden op basis van een overeenkomst van Opdracht in de zin van artikel 7:400 BW en aanverwante wetgeving;
B16: de Partijen uitdrukkelijk overeenkomen geen arbeidsovereenkomst aan te gaan in de zin van artikel 7:610 BW en aanverwante wetgeving;
B18: de Partijen zijn overeengekomen alle afspraken met betrekking tot de Opdracht in deze overeenkomst vast te leggen.
B20: KOMEN ALS VOLGT OVEREEN:
B22: Artikel 1: DE OPDRACHT
B23: De Opdrachtnemer zal voor de Opdrachtgever gedurende de duur van de overeenkomst de volgende werkzaamheden verrichten (de "Opdracht"):
B24: Opdrachtnemer verricht diensten als zijnde: | E24: Vrachtwagenchauffeur
B26: Artikel 2: UITVOERING VAN DE OPDRACHT
B27: De Opdrachtnemer zal bij zijn werkzaamheden de normen van een goede Opdrachtnemer in acht houden en aanvaardt de volledige verantwoordelijkheid de Opdracht op een juiste wijze uit te voeren.
B29: Ingeval de Opdrachtnemer op een bepaald tijdstip verwacht dat hij de Opdracht niet of niet naar behoren kan uitvoeren, dient de Opdrachtnemer de Opdrachtgever hiervan onverwijld op de hoogte te brengen. De Partijen treden alsdan in overleg over mogelijke aanpassingen.
B31: De Opdrachtnemer voert de werkzaamheden met betrekking tot de Opdracht zelfstandig en naar eigen inzicht uit. De Opdrachtgever kan aanwijzingen geven met betrekking tot de uitvoering van de Opdracht.
B33: De Opdrachtgever dient de Opdrachtnemer alle benodigde informatie en zaken ten behoeve van de Opdracht te verstrekken.
B34: De Opdrachtgever is verantwoordelijk en aansprakelijk voor schade die voorkomt uit foutief of onjuist verstrekte informatie of zaken.
B36: Artikel 3: UITBESTEDING AAN DERDEN
B37: De Opdrachtnemer is gerechtigd de Opdracht gedeeltelijk of geheel uit te besteden aan derden.
B39: Artikel 4: VERVANGING
B40: De Opdrachtnemer is in geval van verhindering vrij vervanging aan te wijzen voor de werkzaamheden; De Opdrachtnemer stelt de Opdrachtgever tijdig op de hoogte indien hij verhinderd is in het uitvoeren van de overeenkomst.
B42: Artikel 5: DUUR
B43: De overeenkomst vangt aan op 29 september 2025 voor een onbepaalde duur.
... B46: Ter zake van de uitvoering van de Opdracht zal de Opdrachtnemer van de Opdrachtgever de volgende vergoeding ontvangen:
B47: 28 | C47: euro per gewerkt uur Winkeldistributie
B48: 26 | C48: euro per gewerkt uur Depod
B50: De Opdrachtnemer zal een factuur zenden of doen zenden aan de Opdrachtgever voor de verrichte werkzaamheden. De
B51: factuur zal in ieder geval voldoen aan de wettelijke vereisten en zal worden verzonden op het volgende moment:
B52: Aan het eind van de gewerkte week.
B54: De Opdrachtgever betaalt de factuur zodra de factuur welke door de Opdrachtgever naar de transporteur is verzonden,
B55: is voldaan aan de Opdrachtgever.
B57: De Opdrachtnemer is verantwoordelijk voor alle overige kosten die redelijkerwijs gemaakt worden ten behoeve van de
B58: uitvoering van de Opdracht. De overige kosten kunnen niet verhaald worden op de Opdrachtgever.
B60: Artikel 7: INTELLECTUELE EIGENDOM
B61: De Opdrachtgever behoudt alle intellectuele eigendomsrechten op informatie of zaken die door de Opdrachtgever aan de
...

Sheet Reglement
B1: INTERN REGLEMENT VOOR CHAUFFEURS
B3: Artikel 1: Algemeen
B4: Dit reglement is van toepassing op alle chauffeurs die werkzaamheden verrichten voor het bedrijf, zowel in dienstverband
B5: als ZZP. Het naleven van deze regels is verplicht. Overtredingen kunnen leiden tot sancties, inhoudingen of beëindiging
B6: van samenwerking.
B8: Artikel 2: Documenten en voertuigcontrole
B9: 1. De chauffeur is verantwoordelijk voor het controleren van alle benodigde voertuigdocumenten vóór vertrek:
B10: ■ Verzekering
B11: ■ NIWO-vergunning
B12: ■ Kentekenbewijs
B13: ■ APK
B14: 2. Het voertuig mag niet worden gebruikt als bovenstaande documenten ontbreken.
... B92: Gebruik correcte routes volgens opdrachtgevers:
B93: ■ AH routes: | D93: https://dc-routes.nl/
B94: ■ JUMBO routes: | D94: https://routeboek-prd-we-driver.azurewebsites.net/
B95: ■ PLUS routes: | D95: https://www.werkenbijplus.nl/PlusRoutes/StoreList.aspx
B96: Afwijken van route = verantwoordelijkheid van chauffeur.
B98: Artikel 17: Regels voor ZZP-chauffeurs
B99: 1. Betaling vindt plaats op woensdag.
B100: 2. Uren moeten uiterlijk dinsdag zijn ingediend. Te laat = uitbetaling week later.
B101: 3. Bij vertrek of einde samenwerking wordt één factuur 6 weken vastgehouden i.v.m. boetes.
B102: 4. Bij problemen met betaling van Braven: eerst zelf contact opnemen, daarna assistentie mogelijk.
B104: Artikel 18: ONDERTEKENING
B105: Aldus overeengekomen en in tweevoud opgemaakt en ondertekend:
B107: Datum | C107: : | D107: =FillIn!D52 -> 45978
B112: (Handtekening Opdrachtnemer)
B113: =FillIn!M4 -> de heer G. Aslan

Sheet Правилник
B1: DENIS EXPRESS B.V. - ВЪТРЕШЕН ПРАВИЛНИК ЗА ШОФЬОРИ
B3: Тези разпоредби се отнасят за всички шофьори, работещи за компанията, както наети, така и самонаети.
B4: Настоящият правилник съдържа задължителни инструкции за безопасна, коректна и професионална работа на всички
B5: шофьори. Спазването на правилата е задължително. Неспазването води до санкции и дисциплинарни последици.
B7: 1. Документи и задължения преди тръгване
B8: Всеки шофьор е длъжен преди започване на курса да извърши проверка на автомобила и документите.
B9: Задължително се проверяват и носят:
B10: ● Verzekering (застраховка)
B11: ● Лиценз NIWO
B12: ● Kentekenbewijs (талон)
B13: ● APK (технически преглед)
B14: ● Лична шофьорска карта
... B101: 12. Маршрути
B102: AH Route: | D102: https://dc-routes.nl/
B103: JUMBO Route: | D103: https://routeboek-prd-we-driver.azurewebsites.net/
B104: PLUS Route: | D104: https://www.werkenbijplus.nl/PlusRoutes/StoreList.aspx
B106: 13. Санкции и финансова отговорност
B107: Нарушаването на правилника води до дисциплинарни и или финансови санкции според тежестта на нарушението
B109: Дисциплинарни мерки
B110: ● устно предупреждение
B111: ● писмено предупреждение
B112: ● временно отстраняване от работа
B113: ● прекратяване на договора или сътрудничеството
B115: Финансова отговорност (глоби и удръжки)
B116: Нарушение | H116: Санкция
B117: неспазено предизвестие при напускане | H117: 1500 евро
B118: Eigen risico при щета (самоучастие) | H118: 1500 евро
B119: оронване престижа на фирмата (скандали с клиенти, непристойно поведение, | H119: 2500 евро
B120: агресия, обиди)
B121: оставяне на горивна карта или тахо карта в камиона | H121: 150 евро
B122: загубен ключ, бадж или горивна карта | H122: 250 евро
B123: неправилно използване на Rema кабел водещо до късо съединение | H123: пълна стойност на ремонта
B124: подаване на ток с ABS кабел | H124: пълна стойност на ремонта
B125: оставено ремарке без заключване или без гориво | H125: 250 евро
B126: непредадени документи като dagstaten и листи | H126: 50 евро на ден
B127: неспазване на маршрут или загуба на товар | H127: пълна отговорност
B128: глоби от полиция и институции за скорост, тахограф и други са за сметка на шофьора
B130: 14. Потвърждение
B131: С подписа си удостоверявам, че съм запознат или запозната с правилника и се задължавам да го спазвам
B133: Така договорено, съставено и подписано в два екземпляра:
...

Sheet Regulations
B1: DENIS EXPRESS B.V. – INTERNAL DRIVER REGULATIONS
B3: These provisions apply to all drivers working for the company, both employees and self-employed contractors.
B4: This regulation contains mandatory instructions for the safe, correct, and professional performance of all drivers’ duties.
B5: Compliance with these rules is obligatory. Non-compliance will result in disciplinary and/or financial sanctions.
B7: 1. Documents and Obligations Before Departure
B8: Every driver must check the vehicle and required documents before starting a route.
B9: The following must be verified and carried:
B10: ● Insurance (Verzekering)
B11: ● NIWO Licence
B12: ● Registration Certificate (Kentekenbewijs)
B13: ● APK (Technical Inspection Certificate)
B14: ● Driver licence
... B101: 12. Маршрути
B102: AH Route: | D102: https://dc-routes.nl/
B103: JUMBO Route: | D103: https://routeboek-prd-we-driver.azurewebsites.net/
B104: PLUS Route: | D104: https://www.werkenbijplus.nl/PlusRoutes/StoreList.aspx
B106: 13. Sanctions and Financial Responsibility
B107: Violation of these regulations may lead to disciplinary and/or financial sanctions depending on the severity.
B109: Disciplinary measures:
B110: ● Verbal warning
B111: ● Written warning
B112: ● Temporary suspension
B113: ● Termination of employment or cooperation
B115: Financial liability (fines and deductions):
B116: Violation | H116: Penalty
B117: Leaving employment without notice | H117: 1500 евро
B118: Insurance deductible for damages (Eigen risico) | H118: 1500 евро
B119: Damage to company reputation (misconduct, client conflicts, aggression, offensive behaviour) | H119: 2500 евро
B120: Leaving a fuel or tachograph card in the truck | H120: 150 евро
B121: Lost key, badge, or fuel card | H121: 250 евро
B122: Incorrect use of Rema cable causing a short circuit | H122: Full repair cost
B123: Using ABS cable for jump-starting | H123: Full repair cost
B124: Leaving trailer unlocked or without fuel | H124: 250 евро
B125: Failure to submit daily registers or documents | H125: 50 евро на ден
B126: Route violation or loss of load | H126: Full liability
B127: Fines from police or authorities (speeding, tachograph, etc.) | H127: Paid by driver
B129: 14. Acknowledgement
B130: By signing below, I confirm that I have read and understood these regulations and agree to comply with them.
B132: Signed in duplicate on:
B134: Date | C134: : | D134: =FillIn!D52 -> 45978
...

Sheet Termination
B1: BEËINDIGING ARBEIDSOVEREENKOMST
I3: =FillIn!H4 -> DeNeX Uitzendbureau B.V.
I4: =FillIn!H6 -> Gebroken Meeldijk 66, Unit 1.15
I5: =FillIn!H7&" "&FillIn!H8 -> 2991 VD Barendrecht
B7: ="Aan: "&FillIn!D4 -> Aan: dhr. G. Aslan
B8: =FillIn!D5 -> Bikscotelaan 248 /2/2140 Borgerhout
B9: =FillIn!D6&" "&FillIn!D7 -> 2140 An twerp
B12: Datum: | C12: =FillIn!H8&", "&TEXT(FillIn!D38,"dd mmmm YYYY") -> Barendrecht, 02 november 2025
B13: Betreft: | C13: Beëindiging Arbeidsovereenkomst
B17: ="Geachte "&FillIn!M3&" "&FillIn!N3&"," -> Geachte heer G. Aslan,
B19: ="Hierbij delen wij u mede, dat uw arbeidsovereenkomst per "&IF(FillIn!D12>FillIn!F14,TEXT(FillIn!D12,"dd mmmm yyyy")," tijdens proeftijd "&TEXT(FillIn!D12,"dd mmmm yyyy"))&" wordt beëindigd. U heeft bij ons bedrijf vanaf "&TEXT(FillIn!D11,"dd mmmm yyyy")&" tot en met "&TEXT(FillIn!D12,"dd mmmm yyyy")&"." -> Hierbij delen wij u mede, dat uw arbeidsovereenkomst per 17 mei 2026 wordt beëindigd. U heeft bij ons bedrijf vanaf 18 november 2025 tot en met 17 mei 2026.
B21: Wij bedanken u voor uw inzet en wensen u veel succes voor het vinden van een nieuwe baan.
B22: Hopende u hierbij voldoende te hebben geïnformeerd.
B24: Met vriendelijke groet,
B30: =FillIn!M5 -> de heer D.O. Ibryam

Sheet SelfT
B1: ZELF ONTSLAG
I3: =FillIn!D4 -> dhr. G. Aslan
I4: =FillIn!D5 -> Bikscotelaan 248 /2/2140 Borgerhout
I5: =FillIn!D6&" "&FillIn!D7 -> 2140 An twerp
B7: ="Aan: "&FillIn!H4 -> Aan: DeNeX Uitzendbureau B.V.
B8: =FillIn!H6 -> Gebroken Meeldijk 66, Unit 1.15
B9: =FillIn!H7&" "&FillIn!H8 -> 2991 VD Barendrecht
B12: Datum: | C12: =FillIn!H8&", "&TEXT(FillIn!D38,"dd mmmm YYYY") -> Barendrecht, 02 november 2025
B13: Betreft: | C13: Zelf ontslag
B17: ="Geachte "&FillIn!N5&"," -> Geachte heer D.O. Ibryam,
B19: ="Hierbij deel ik u mede dat ik zelf ontslag neem per "&TEXT(FillIn!D12,"dd mmmm yyyy")&". Ik zeg mijn arbeidsovereenkomst op per "&TEXT(FillIn!D12,"dd mmmm yyyy")&" en teven is dat mijn laatste werkdag bij uw bedrijf." -> Hierbij deel ik u mede dat ik zelf ontslag neem per 17 mei 2026. Ik zeg mijn arbeidsovereenkomst op per 17 mei 2026 en teven is dat mijn laatste werkdag bij uw bedrijf.
B21: Wij bedanken u voor uw inzet en wensen u veel succes voor het vinden van een nieuwe baan.
B22: Hopende u hierbij voldoende te hebben geïnformeerd.
B24: Met vriendelijke groet,
B30: =FillIn!M3&" "&FillIn!N3 -> heer G. Aslan

Sheet Unpaid
B1: BEVESTIGING ONBETAALD VERLOF
B5: ="Geachte "&FillIn!M3&" "&FillIn!N3&"," -> Geachte heer G. Aslan,
B7: ="Wij willen u graag laten weten dat uw aanvraag voor onbetaald verlof is goedgekeurd. U heeft recht op "&FillIn!H34&" "&FillIn!H35&" "&" onbetaald verlof, beginnend op "&TEXT(FillIn!H36,"dd mmmm yyyy")&" en derhalve eindigend op "&TEXT(FillIn!H37,"dd mmmm yyyy")&"." -> Wij willen u graag laten weten dat uw aanvraag voor onbetaald verlof is goedgekeurd. U heeft recht op 129 dagen onbetaald verlof, beginnend op 18 november 2025 en derhalve eindigend op 17 mei 2026.
B9: Tijdens uw verlof zult u geen werkgerelateerde taken uitvoeren. U dient de voorwaarden voor het opnemen van onbetaald verlof te volgen, zoals beschreven in ons personeelsreglement.
B11: Wij begrijpen dat deze situatie voor u belangrijk is. Wij hopen dat het verlof u de tijd en ruimte zal geven om te doen wat u nodig heeft en dat alles goed zal verlopen.
B13: Als u nog vragen heeft over het onbetaald verlof of de voorwaarden die daarvoor gelden, aarzel dan niet om contact op te nemen met onze HR-afdeling.
B15: Met vriendelijke groet,
B21: =FillIn!M5 -> de heer D.O. Ibryam

Sheet Annex
B1: Addendum arbeidsovereenkomst
B3: Ondergetekenden:
B4: Naam bedrijf: | E4: =FillIn!H4 -> DeNeX Uitzendbureau B.V.
B5: Rechtsgeldig vertegenwoordigd door: | E5: =FillIn!M5 -> de heer D.O. Ibryam
B6: Adres: | E6: =FillIn!H6 -> Gebroken Meeldijk 66, Unit 1.15
B7: Postcode en vestigingsplaats: | E7: =FillIn!H7&" "&FillIn!H8 -> 2991 VD Barendrecht
B9: Hierna te noemen: werkgever,
B11: en
B13: Naam werknemer: | E13: =FillIn!M4 -> de heer G. Aslan
B14: Adres: | E14: =FillIn!D5 -> Bikscotelaan 248 /2/2140 Borgerhout
B15: Postcode en woonplaats: | E15: =FillIn!D6&" "&FillIn!D7 -> 2140 An twerp
B16: Geboortedatum: | E16: =FillIn!D8 -> 29310
B18: Hierna te noemen: werknemer,
B20: Overwegende:
B22: - dat partijen het wenselijk achten om deze nadere afspraken schriftelijk vast te leggen in dit addendum.
B24: Verklaren hierbij te zijn overeengekomen als volgt:
B25: 1. In aanvulling en/of afwijking op de arbeidsovereenkomst komen partijen overeen dat
B27: =IF(FillIn!D40>0,"Werknemer met ingang van "&TEXT(FillIn!D38,"dd mmmm yyyy")&" is ingedeeld in functie: "&FillIn!D40&".",IF(FillIn!D42>0,"De arbeidsduur van de werknemer met ingang van "&TEXT(FillIn!D38,"dd mmmm yyyy")&" bedraagt "&FillIn!D42&" uur per week.",IF(FillIn!D45>0,"Werknemer met ingang van "&TEXT(FillIn!D38,"dd mmmm yyyy")&" werkt op de dagen "&FillIn!D44&" van "&TEXT(FillIn!D45,"hh:mm")&" tot "&TEXT(FillIn!D46,"hh:mm")&" uur.",IF(FillIn!D48>0,"Werknemer met ingang van "&TEXT(FillIn!D38,"dd mmmm yyyy")&" is ingedeeld in functiegroep: "&FillIn!D48&" met functiejaar "&FillIn!D49&"."," - ")))) -> Werknemer met ingang van 02 november 2025 werkt op de dagen za zo van 07:00 tot 19:00 uur.
B29: 2. Dit addendum zal aan de geldende arbeidsovereenkomst worden gehecht en maakt - na ondertekening onlosmakelijk onderdeel uit van de arbeidsovereenkomst.
B30: 3. De overige bepalingen, zoals opgenomen in de arbeidsovereenkomst, blijven onverkort van toepassing.
B32: ="Aldus overeengekomen en in tweevoud opgemaakt te "&FillIn!H8&" op "&TEXT(FillIn!D38-3,"dd mmmm yyyy")&"." -> Aldus overeengekomen en in tweevoud opgemaakt te Barendrecht op 30 oktober 2025.
B34: ="Namens werkgever "&FillIn!H4 -> Namens werkgever DeNeX Uitzendbureau B.V. | H34: Werknemer
B39: ___________________ | H39: _________________
B40: =FillIn!M5 -> de heer D.O. Ibryam | H40: =FillIn!M4 -> de heer G. Aslan

Sheet AgrTM
B2: Vervoermanagement overeenkomst
B4: De ondergetekenden:
B6: ="1. "&FillIn!H4&", gevestigd aan de "&FillIn!H6&", "&FillIn!H7&" "&FillIn!H8&", rechtsgeldig vertegenwoordigd door haar directeur, "&FillIn!M5&", hierna te noemen Opdrachtgever oftewel de transportonderneming," -> 1. DeNeX Uitzendbureau B.V., gevestigd aan de Gebroken Meeldijk 66, Unit 1.15, 2991 VD Barendrecht, rechtsgeldig vertegenwoordigd door haar directeur, de heer D.O. Ibryam, hierna te noemen Opdrachtgever oftewel de transportonderneming,
B8: en
B10: ="2. "&FillIn!M4&IF(FillIn!H14="Intern",", woonachtig",", hodn "&FillIn!G47&", kantoor houdende")&" aan de "&FillIn!D5&", "&FillIn!D6&" "&FillIn!D7&", hierna te noemen "&IF(FillIn!H14="Intern","Werknemer ","externe Opdrachtnemer ")&" oftewel vervoersmanager,""" -> 2. de heer G. Aslan, woonachtig aan de Bikscotelaan 248 /2/2140 Borgerhout, 2140 An twerp, hierna te noemen Werknemer oftewel vervoersmanager,"
B12: komen overeen als volgt:
B14: Artikel 1
B16: ="a. Vervoermanager zal per "&TEXT(FillIn!D11,"dd mmmm yyyy")&IF(FillIn!D12>0," tot en met "&TEXT(FillIn!D12,"dd mmmm yyyy"),"")&" in opdracht van opdrachtgever het management voeren over de onderneming." -> a. Vervoermanager zal per 18 november 2025 tot en met 17 mei 2026 in opdracht van opdrachtgever het management voeren over de onderneming.
B18: b. Onder het voeren van management wordt verstaan het leidinggeven aan de vervoersactiviteiten in de meest ruime zin van het woord.
B20: Het takenpakket betreft onder meer, maar is niet beperkt tot, de volgende werkzaamheden:
B21: - Aanschaf en beheer materieel;
B22: - Calculatie en vaststelling vrachtprijs;
B23: - Werkverdeling;
B24: - Debiteuren/crediteurenbewaking;
B25: - Aanname/ontslag personeel;
B26: - Klachtenafhandeling.
B28: Artikel 2
B30: ="a. Deze overeenkomst is aangegaan voor "&IF(FillIn!D12>0,"bepaalde ","onbepaalde ")&"tijd. Elk van partijen kan de overeenkomst opzeggen met inachtneming van een opzegtermijn van "&FillIn!D18&"." -> a. Deze overeenkomst is aangegaan voor bepaalde tijd. Elk van partijen kan de overeenkomst opzeggen met inachtneming van een opzegtermijn van 1 maand.
B32: b. De opzegging dient schriftelijk te geschieden.
B34: c. Ieder van partijen is gerechtigd deze overeenkomst met onmiddellijke ingang, zonder ingebrekestelling of gerechtelijke tussenkomst, op te zeggen indien:
B36: - Opdrachtgever of de Vervoersmanager surseance van betaling aanvraagt, in faillissement treedt of in liquidatie treedt;
B37: - Opdrachtgever of de Vervoersmanager of diens werknemer(s) die betrokken zijn bij de uitvoering van deze overeenkomst strafrechtelijk wordt/worden vervolgd;
B38: - de zeggenschap over opdrachtgever of de Vervoersmanager wijzigt als gevolg van aandeelhouderswisselingen.
B42: Artikel 3
B44: ="De managementvergoeding is € "&FillIn!D19&" per maand, gebaseerd op "&FillIn!H15&" voertuig(en). De totale vergoeding die opdrachtgever aan de vervoermanager verschuldigd is bedraagt € "&IF(FillIn!H14="Intern",FillIn!D19&" - euro per maand. ",FillIn!H19&" - euro per maand, inclusief omzetbelasting. ")&" De managementvergoeding wordt maandelijks voldaan. De vergoeding zal jaarlijks kunnen worden herzien. Partijen zullen omtrent een eventuele herziening overleg plegen. In totaal zal de vervoermanager "&FillIn!H16&" uur per week voor opdrachtgever werkzaamheden verrichten." -> De managementvergoeding is € 350 per maand, gebaseerd op 6 voertuig(en). De totale vergoeding die opdrachtgever aan de vervoermanager verschuldigd is bedraagt € 350 - euro per maand. De managementvergoeding wordt maandelijks voldaan. De vergoeding zal jaarlijks kunnen worden herzien. Partijen zullen omtrent een eventuele herziening overleg plegen. In totaal zal de vervoermanager 40 uur per week voor opdrachtgever werkzaamheden verrichten.
B46: Partijen hebben zich ervan vergewist dat heffing van loonbelasting en werknemersverzekeringspremies ter zake van de uit te betalen managementvergoeding achterwege kan blijven.
B48: Artikel 4
B50: De Vervoersmanager verplicht zich alles te doen c.q. na te laten wat een goed manager behoort te doen c.q. na te laten, en zich volledig in te zetten om de belangen van opdrachtgever te bevorderen.
B52: Artikel 5
B54: Opdrachtgever zal de Vervoersmanager vrijwaren voor eventuele aanspraken van derden voor zover die aanspraken betrekking hebben op of verband houden met de werkzaamheden die de Vervoersmanager binnen de onderneming van opdrachtgever vervult of heeft vervuld.
B56: Artikel 6
B58: De Vervoersmanager is verplicht tot volstrekte geheimhouding, ook na het einde van deze overeenkomst, van al hetgeen hem uit hoofde van zijn functie binnen de onderneming van opdrachtgever in de ruimste zin bekend is of zal worden, voor zover door de bekendmaking van die wetenschap de belangen van opdrachtgever kunnen worden geschaad.
B60: ="Aldus overeengekomen, opgemaakt in tweevoud en getekend te "&FillIn!H8&" op "&TEXT(FillIn!D52,"dd mmmm yyyy")&"." -> Aldus overeengekomen, opgemaakt in tweevoud en getekend te Barendrecht op 17 november 2025.
B62: Opdrachtgever | H62: De Vervoersmanager
B67: ………………………….. | H67: …………………………..
B68: =FillIn!M5 -> de heer D.O. Ibryam | H68: =FillIn!M50 -> deheer A.A. Kazakov

Sheet AgrLoan
B1: Inleenovereenkomst
B3: De Uitlener / Uitzendonderneming
B5: Naam | F5: =FillIn!H4 -> DeNeX Uitzendbureau B.V.
B6: Adres | F6: =FillIn!H6&", "&FillIn!H7&" "&FillIn!H8 -> Gebroken Meeldijk 66, Unit 1.15, 2991 VD Barendrecht
B7: Contactpersoon | F7: =FillIn!M5 -> de heer D.O. Ibryam
B8: BTW nummer | F8: =FillIn!H10 -> NL863179344B01
B9: KvK Nummer | F9: =FillIn!H11 -> 84349735
B10: E-mail | F10: =VLOOKUP(FillIn!H3,CRM,14,TRUE) -> info@denexuitzendbureau.nl
B11: Telefoon | F11: =FillIn!H9 -> +31628813127
B13: en
B15: De Inlener / Transport Onderneming
B17: Naam | F17: =FillIn!G47 -> A.A. Kazakov
B18: Adres | F18: =FillIn!H48&", "&FillIn!H49&" "&FillIn!I49 -> Loosduinseweg 867, 2571AV s-Gravenhage
B19: Contactpersoon | F19: =FillIn!M50 -> deheer A.A. Kazakov
B20: BTW nummer | F20: =VLOOKUP(FillIn!$G$47,CRM,12,TRUE) -> NL003657916B47
B21: KvK Nummer | F21: =FillIn!$H$51 -> 82225443
B22: E-mail | F22: =VLOOKUP(FillIn!G47,CRM,14,TRUE) -> kazakovasen5@gmail.com
B23: Telefoon | F23: =VLOOKUP(FillIn!G47,CRM,9,TRUE) -> 0685411440
B25: in aanmerking nemende:
B27: ● | C27: dat Inlener een transportonderneming exploiteert;
B28: ● | C28: dat Uitlener een instelling als bedoeld in artikel 13 lid 2 sub b Regeling Wegvervoer Goederen exploiteert;
B29: ● | C29: dat Inlener in dat kader nu en in de toekomst mogelijk overeenkomsten wenst aan te gaan met Uitlener, bestaande uit het door Uitlener aan Inlener ter beschikking stellen van zelfstandige chauffeurs;
B30: ● | C30: dat Uitlener bereid is opdrachten aan te nemen en uit te voeren ten behoeve van het bedrijf van Inlener;
B31: ● | C31: dat Partijen overeen zijn gekomen zich uitsluitend te verbinden op basis van een overeenkomst van opdracht in de zin van artikel 7:400 BW en aanverwante wetgeving;
B32: ● | C32: dat Partijen uitdrukkelijk overeenkomen geen arbeidsovereenkomst aan te gaan in de zin van artikel 7:610 BW en aanverwante wetgeving;
B33: ● | C33: dat partijen de afspraken die steeds van toepassing zullen zijn bij (de uitvoering van) deze overeenkomst(en) willen vastleggen in deze overeenkomst, welke gezien dient te warden als raamovereenkomst voor de huidige en toekomstige overeenkomst( en).
B35: De individuele overeenkomsten die tot stand komen tussen Inlener en Uitlener en de lopende overeenkomst(en) zullen steeds worden beheerst door de volgende voorwaarden:
B37: 1. Toepassing van de Juiste Arbeidsvoorwaarden door de Uitlener
B39: Deze raamovereenkomst met bijlagen is steeds van toepassing op alle door partijen nader te sluiten overeenkomsten terzake het door Uitlener aan Inlener beschikbaar stellen van chauffeurs, ook zonder enige verwijzing daarnaar in de door Inlener geplaatste opdrachten c.q. de eventueel door Uitlener verstrekte opdrachtbevestigingen.
B41: De Uitlener is verantwoordelijk voor het toepassen van de juiste arbeidsvoorwaarden voor de geleverde uitzendkrachten (chauffeurs). De volgende arbeidsvoorwaarden zijn van toepassing:
B43: Salaris en Vergoedingen: De uitzendkracht ontvangt ten minste het wettelijke minimumloon of de caobepalingen die van toepassing zijn binnen de sector en voor de specifieke functie (zoals de cao voor het Bedrijfsgoederenvervoer).
B44: Werktijden en Rusttijden: De werktijden, pauzes en rusttijden worden overeenkomstig de geldende wetgeving en CAO Bedrijfsgoederenvervoer vastgesteld.
B45: Verlofregelingen: De uitzendkracht heeft recht op vakantiedagen, ziekteverlof en andere vergoedingen zoals voorgeschreven in de wet en CAO Bedrijfsgoederenvervoer.
B46: Pensioenregeling: De uitzendkracht wordt opgenomen in een pensioenregeling zoals bepaald door de wet en de CAO Bedrijfsgoederenvervoer.
B47: De Uitlener zal de uitzendkracht informeren over zijn rechten en verplichtingen volgens de geldende arbeidswetgeving en cao.
B49: 2. Algemeen
B51: 1. | C51: Inlener kan Uitlener verzoeken te bemiddelen in het ter beschikking stellen van chauffeurs aan Inlener, voor door Inlener te bepalen chauffeurswerkzaamheden en voor een door Inlener te bepalen periode.
B52: 2. | C52: Inlener is verplicht Uitlener te voorzien van alle informatie die Uitlener nodig heeft om de aangenomen opdracht goed te kunnen uitvoeren.
B53: 3. | C53: Met betrekking tot de uit te voeren werkzaamheden zal door partijen steeds een deelovereenkomst worden gesloten. In deze deelovereenkomst kan het volgende warden vastgelegd:
C54: ● | D54: Omschrijving van de uit te voeren werkzaamheden;
...

Sheet AgrPlan
B1: Arbeidsovereenkomst bepaalde tijd – Planner Vervoer over de Weg
B3: De ondergetekenden:
B5: 1. De uitzendonderneming DeNeX Uitzendbureau B.V. gevestigd te Barendrecht aan de Gebroken Meeldijk 66, Unit 1.15 , 2991 VD, vertegenwoordigd door dhr. D.O. Ibryam , hierna te noemen: werkgever;
B7: 2. mw. S.E. Fidanova, geboren op 09 juli 1986, wonende te Florastraat 49, 2672 HL NAALDWIJK, hierna te noemen: werknemer;
B9: verklaren het volgende te zijn overeengekomen:
B11: Artikel 1 – Duur van de overeenkomst
B13: Deze arbeidsovereenkomst wordt aangegaan voor bepaalde tijd, te weten 7 maanden, ingaande op 04 juni 2025 en eindigende van rechtswege op 03 januari 2026, zonder dat opzegging vereist is.
B15: Artikel 2 – Proeftijd
B16: Dit arbeidscontract is aangegaan met inachtneming van een wederzijdse proeftijd van 1 maand. Gedurende deze proeftijd kunnen beide partijen het arbeidscontract met directe ingang beëindigen. Een schriftelijke bevestiging hiervan is niet benodigd. De proeftijd is van toepassing indien een dienstverband voor een minimale duur van 12 maanden is aangegaan.
B18: Artikel 3 – Functie en werkzaamheden
B20: Werknemer treedt in dienst in de functie van Planner Vervoer over de Weg. Hij/Zij verricht alle werkzaamheden die in redelijkheid van hem/haar in deze functie mogen worden verwacht, alsmede alle andere werkzaamheden die door werkgever worden opgedragen en die verband houden met de onderneming.
B22: Artikel 4 – Arbeidsduur en werktijden
... B67: Artikel 10 – Toepasselijk recht en geschillen
B69: ="Op deze overeenkomst is Nederlands recht van toepassing. Geschillen zullen bij uitsluiting worden voorgelegd aan de bevoegde rechter te "&FillIn!H8&"." -> Op deze overeenkomst is Nederlands recht van toepassing. Geschillen zullen bij uitsluiting worden voorgelegd aan de bevoegde rechter te Barendrecht.
B71: ="Aldus overeengekomen en in tweevoud getekend te "&FillIn!H8&" op "&TEXT(FillIn!D52,"dd mmmm yyyy")&"." -> Aldus overeengekomen en in tweevoud getekend te Barendrecht op 17 november 2025.
B73: Werkgever | G73: Werknemer
B74: ="Naam: "&FillIn!M5 -> Naam: de heer D.O. Ibryam | G74: ="Naam: "&FillIn!M4 -> Naam: de heer G. Aslan
B79: Handtekening: ...................................... | G79: Handtekening: ......................................

Sheet AODriver
B1: ="ARBEIDSOEVEENKOMST VOOR "&IF(FillIn!D12>0,"BEPAALDE","ONBEPAALDE")&" TIJD" -> ARBEIDSOEVEENKOMST VOOR BEPAALDE TIJD
B3: De ondergetekenden:
B4: Werkgever: | G4: Werknemer:
B5: Bedrijfsnaam | C5: : | D5: =FillIn!H4 -> DeNeX Uitzendbureau B.V. | G5: Naam | H5: : | I5: =FillIn!M4 -> de heer G. Aslan
B6: Adres | C6: : | D6: =FillIn!H6 -> Gebroken Meeldijk 66, Unit 1.15 | G6: Adres | H6: : | I6: =FillIn!D5 -> Bikscotelaan 248 /2/2140 Borgerhout
B7: Postcode/Plaats | C7: : | D7: =FillIn!H7&" "&FillIn!H8 -> 2991 VD Barendrecht | G7: Postcode /Plaats | H7: : | I7: =FillIn!D6&" "&FillIn!D7 -> 2140 An twerp
B8: Contact | C8: : | D8: =FillIn!M5 -> de heer D.O. Ibryam | G8: Geb.datum | H8: : | I8: =FillIn!D8 -> 29310
G9: BSN: | H9: : | I9: =FillIn!D9 -> 235116026
B10: zijn het volgende overeengekomen:
B12: Artikel 1: Datum indiensttreding, functie en plaats werkzaamheden
B13: ="Er is een dienstverband aangegaan met ingang van: "&TEXT(FillIn!D11,"dd mmmm yyyy")&IF(FillIn!D12>0," tot "&TEXT(FillIn!D12,"dd mmmm yyyy")&".",".") -> Er is een dienstverband aangegaan met ingang van: 18 november 2025 tot 17 mei 2026.
B15: ="De werknemer is aangenomen voor de functie van "&FillIn!D13&"." -> De werknemer is aangenomen voor de functie van Chauffeur.
B17: De bij deze functie behorende werkzaamheden bestaan uit: Het vervoeren van goederen over weg en voorts alle werkzaam­heden die redelijkerwijs van hem verlangd kunnen worden. De werkzaamheden worden uitgevoerd vanuit de vestiging van werkgever of opdrachtgevers van werkgever.
B19: Artikel 2: Proeftijd
B20: =IF(FillIn!D14>0,"Dit arbeidscontract is aangegaan met inachtneming van een wederzijdse proeftijd van "&FillIn!D14&". Gedurende deze proeftijd kunnen beide partijen het arbeidscontract met directe ingang beëindigen. Een schriftelijke bevestiging hiervan is niet benodigd. De proeftijd is van toepassing indien een dienstverband voor een minimale duur van 12 maanden is aa"&"ngegaan.","Er is geen proeftijd bij het aangaan van de dienstverband.") -> Er is geen proeftijd bij het aangaan van de dienstverband.
B22: Artikel 3: Arbeidsduur, werktijden en overwerk
B23: ="De wekelijkse arbeidsduur bedraagt "&FillIn!D15&"." -> De wekelijkse arbeidsduur bedraagt 40 uur per week.
B24: ="Werknemer verklaart op de hoogte te zijn van en in te stemmen met de door werkgever geregelde wekelijkse planning voor "&FillIn!D16&". Werknemer is tevens op de hoogte gesteld dat de werktijden tussen "&FillIn!D17&" kunnen plaatsvinden. Werknemer is redelijkerwijs verplicht gehoor te geven aan een redelijk verzoek van ­werkgever om overwerk te verrichten." -> Werknemer verklaart op de hoogte te zijn van en in te stemmen met de door werkgever geregelde wekelijkse planning voor maandag t/m vrijdag. Werknemer is tevens op de hoogte gesteld dat de werktijden tussen tussen 7:00 uur t/m 19:00 uur kunnen plaatsvinden. Werknemer is redelijkerwijs verplicht gehoor te geven aan een redelijk verzoek van ­werkgever om overwerk te verrichten.
B26: Artikel 4: Salaris
B27: ="Werknemer ontvangt conform de cao en loonschaal "&FillIn!D21&" en trede "&FillIn!D22&" een salaris van € "&FillIn!D24&" bruto per uur door werkgever te voldoen voor of op de laatste dag van de maand." -> Werknemer ontvangt conform de cao en loonschaal D en trede 5 een salaris van € 18,71 bruto per uur door werkgever te voldoen voor of op de laatste dag van de maand.
B29: Artikel 5: Reiskostenvergoeding
B30: ="De werknemer ontvangt geen vergoeding voor de reiskosten woon-werkverkeer. Indien achteraf hierover schriftelijk wordt overeengekomen bedraagt de vergoeding maximaal € "&FillIn!D25&" per gereisde kilometer met een maximum reiskostenvergoeding van € "&FillIn!D26&" per maand. De reiskostenvergoeding is onbelast en maakt geen deel uit van het loon van de werknemer." -> De werknemer ontvangt geen vergoeding voor de reiskosten woon-werkverkeer. Indien achteraf hierover schriftelijk wordt overeengekomen bedraagt de vergoeding maximaal € 0,23 per gereisde kilometer met een maximum reiskostenvergoeding van € 100 per maand. De reiskostenvergoeding is onbelast en maakt geen deel uit van het loon van de werknemer.
B32: Artikel 6: Salaris bij arbeidsongeschiktheid en wachtdagen
B33: 1. In geval van arbeidsongeschiktheid wegens ziekte, ongeval en dergelijke, zal werkgever, indien en zolang in die periode het dienstverband voortduurt, gedurende de eerste 104 weken van arbeidsongeschiktheid 70% van het brutoloon door­betalen, doch gedurende de eerste 52 weken ten minste het voor werknemer geldende ­minimumloon.
B34: 2. Werknemer verklaart op de hoogte te zijn van en in te stemmen met de door werkgever vastgestelde voorschriften in verband met ziekmelding en controle.
B35: 3. Wegens ziekte of arbeidsongeschiktheid heeft de werknemer gedurende de eerste dag van een ziekteperiode geen recht op loon. Dit geldt niet indien werknemer na het einde van een ziekteperiode binnen vier weken wederom ziek wordt.
B37: Artikel 7: Re-integratie na einde dienstverband
B38: - Werknemer is verplicht zich onmiddellijk ziek te melden bij werkgever conform de door werkgever vastgestelde voorschriften in verband met ziekmelding en controle als werknemer binnen 4 weken na het einde van de arbeidsovereenkomst ziek wordt en op dat moment niet werkzaam is bij een andere werkgever of een WW-uitkering ontvangt.
B39: - Als werknemer ziek is op het moment dat hij uit dienst gaat en/of als werknemer voldoet aan het bepaalde in lid 1 van dit artikel, dient werknemer zich te blijven houden aan de door werkgever of regelgeving vastgestelde voorschriften in verband met ziekmelding en controle.
B40: - Indien werknemer bovenstaande van de in dit artikel bepaalde overtreedt, verbeurt hij aan werkgever een direct opeisbare boete van 2.500,- voor iedere overtreding, alsmede een bedrag van 500,- voor iedere dag dat de overtreding voortduurt. De boete zal verschuldigd zijn door het enkele feit van de overtreding of niet-nakoming, maar laat onverminderd het recht om volledige schadevergoeding te vorderen. Deze boete is rechtsreeks verschuldigd aan werkgever en strekt deze tot voordeel. Hiermee wordt nadrukkelijk afgeweken van het bepaalde in artikel 7:650 leden 3 en 5 BW.
B42: Artikel 8: Vakantiedagen, ATV en vakantiebijslag
B43: ="Werknemers van "&FillIn!D32&" hebben recht op "&FillIn!D33&" vakantiedagen per kalenderjaar ("&VALUE(LEFT(FillIn!D33,2))-4&" wettelijke en 4 dagen bovenwettelijke) met behoud van salaris." -> Werknemers van 45 t/m 49 jaar hebben recht op 25 dagen vakantiedagen per kalenderjaar (21 wettelijke en 4 dagen bovenwettelijke) met behoud van salaris.
B44: Bij andere leeftijden gelden andere rechten, zie hiervoor artilkel 67a van het cao. Van de vakantiedagen mogen maximaal drie weken worden opgenomen in een aaneengesloten periode. ")Verlofdagen worden vastgesteld door de werkgever, na overleg met de werknemerVerlofdagen worden vastgesteld door de werkgever, na overleg met de werknemer. Werkgever is bevoegd maximaal 14 dagen per jaar als verplichte vakantiedagen aan te wijzen. Tevens is het mogelijk dat een periode (maximaal één maand) wordt aangewezen i.v.m. bedrijfssluiting. Deze wordt door werkgever als verplichte vakantie aangewezen. Deze vakantiedagen komen in mindering op het vakantietegoed.
B45: ="Werknemer heeft recht op "&FillIn!D34&" ATV dagen per kalenderjaar met behoud van salaris. Per jaar heeft de werknemer recht op een vakantiebijslag van "&TEXT(FillIn!D35,"0.00%")&" over het op jaarbasis berekende brutosalaris." -> Werknemer heeft recht op 3,5 ATV dagen per kalenderjaar met behoud van salaris. Per jaar heeft de werknemer recht op een vakantiebijslag van 8,00% over het op jaarbasis berekende brutosalaris.
B46: ="Werknemer ontvangt in de maanden mei en november de vakantiebijslag van "&TEXT(FillIn!D35,"0.00%")&" naar ratio tezamen met de maandelijkse salaris. Bij tussentijdse aanvang of beëindiging van het dienstverband worden de vakantie­rechten naar rato van het aantal maanden dat werknemer in dienst is, vastgesteld." -> Werknemer ontvangt in de maanden mei en november de vakantiebijslag van 8,00% naar ratio tezamen met de maandelijkse salaris. Bij tussentijdse aanvang of beëindiging van het dienstverband worden de vakantie­rechten naar rato van het aantal maanden dat werknemer in dienst is, vastgesteld.
B48: Artikel 9: Arbeids- en bedrijfsregels
B49: Werknemer verklaart op de hoogte te zijn van en in te stemmen met de bij werkgever geldende arbeids- en bedrijfsregels en een exemplaar van deze arbeids- en bedrijfsregels te hebben ontvangen.
B51: Artikel 10: Schadeclausule bij niet nakomen van verplichtingen
B52: Indien werknemer om wat voor reden dan ook de arbeidsovereenkomst c.q. de werkzaamheden eenzijdig beëindigt zonder hier werkgever van tevoren van op de hoogte te stellen of zich niet houdt aan de geldende opzegtermijn is werknemer schadeplichtig. In afwijking van art. 7:650 leden 3 en 5 BW zal werknemer in dat geval een onmiddellijk opeisbare tot voordeel van de werkgever strekkende boete verbeuren van € 250,00 ineens (welke direct al wordt ingehouden op het salaris van werknemer) onverminderd het recht van werkgever om in plaats van deze boete, schadevergoeding te vorderen. Eveneens staat de werknemer de inhouding van de schadevergoeding op het loon toe rekening houdend met WML.
B54: Artikel 11: Wijzigingen
...

Sheet TempAO
B1: UITZENDOVEREENKOMST FASE A
B3: De ondergetekenden:
B4: Partijen:
B5: 1. | C5: ="De uitzendonderneming "&FillIn!H4&" gevestigd te Rijswijk aan de "&FillIn!H6&", "&FillIn!H7&", te "&FillIn!H8&" vertegenwoordigd door "&FillIn!M5&"." -> De uitzendonderneming DeNeX Uitzendbureau B.V. gevestigd te Rijswijk aan de Gebroken Meeldijk 66, Unit 1.15, 2991 VD, te Barendrecht vertegenwoordigd door de heer D.O. Ibryam.
C7: hierna te noemen : | F7: Werkgever
C9: en
B11: 2. | C11: De medewerker: | F11: =FillIn!M4 -> de heer G. Aslan
C12: Adres: | F12: =FillIn!D5 -> Bikscotelaan 248 /2/2140 Borgerhout
C13: Plaats: | F13: =FillIn!D6&" "&FillIn!D7 -> 2140 An twerp
C14: Geboortedatum: | F14: =FillIn!D8 -> 29310
C15: BSN: | F15: =FillIn!D9 -> 235116026
C17: Partij nader te noemen | F17: Werknemer
B19: ZIJN MET ELKAAR OVEREENGEKOMEN:
B21: Artikel 1: | D21: Functie
B22: 1.1. | C22: ="Per "&TEXT(FillIn!D11,"dd mmmm yyyy")&" treedt "&FillIn!M4&" indienst bij "&FillIn!H4&" voor de duur van de projecten welke "&FillIn!H4&" heeft afgesloten met verschillende opdrachtgevers." -> Per 18 november 2025 treedt de heer G. Aslan indienst bij DeNeX Uitzendbureau B.V. voor de duur van de projecten welke DeNeX Uitzendbureau B.V. heeft afgesloten met verschillende opdrachtgevers.
B23: 1.2. | C23: =FillIn!M4&" zal als "&FillIn!D13&" worden ingezet voor de arbeidsduur van "&FillIn!D15&"." -> de heer G. Aslan zal als Chauffeur worden ingezet voor de arbeidsduur van 40 uur per week.
C24: ="Naar verwachting zal de arbeidsovereenkomst doorlopen tot "&TEXT(FillIn!H41,"dd mmmm yyyy")&". " -> Naar verwachting zal de arbeidsovereenkomst doorlopen tot 17 juni 2026.
C25: =FillIn!M4&" werkt onder toezicht van de opdrachtgever voor wie werknemer de werkzaamheden gaat verrichten." -> de heer G. Aslan werkt onder toezicht van de opdrachtgever voor wie werknemer de werkzaamheden gaat verrichten.
B26: 1.3. | C26: Proeftijd conform artikel 16 CAO ABU, dhr. N.V. Stoev kan de CAO ABU nalezen op www.ABU.nl.
B28: Artikel 2: | D28: CAO ABU
B29: Op deze arbeidsovereenkomst is tevens de Collectieve Arbeidsovereenkomst voor Uitzendkrachten (CAO ABU,
B30: https://www.abu.nl/app/uploads/2024/12/ABU-CAO-Uitzendkrachten-2024.pdf) van toepassing.
B32: Artikel 3: | D32: Uitzendbeding
B33: 3.1. | C33: Op deze uitzendovereenkomst is de bepaling ex artikel 7:691 lid 2 BW in combinatie met de artikelen 12 en 13 van de CAO ABU van toepassing. Dat betekent dat de uitzendovereenkomst van rechtswege eindigt doordat de terbeschikkingstelling van de uitzendkracht door de uitzendonderneming aan de opdrachtgever op verzoek van de opdrachtgever ten einde komt.
B34: 3.2 | C34: Indien fase A van toepassing is, wordt de arbeidsovereenkomst als beëindigd beschouwd ingeval van ziekte of ongeval. Als moment voor de beëindiging geldt alsdan de datum van ziekmelding bij de opdrachtgever en/of de werkgever.
B36: Artikel 4: | D36: Loon, inhouding en vergoedingen
B37: ="Het bruto uurloon bedraagt: € "&FillIn!D24&" en zal door "&FillIn!H4&" worden voldaan op basis van een 40 urige werkweek." -> Het bruto uurloon bedraagt: € 18,71 en zal door DeNeX Uitzendbureau B.V. worden voldaan op basis van een 40 urige werkweek.
B38: Bij beëindiging van de arbeidsovereenkomst wordt gedurende zes weken een bedrag van € 500,- van het uit te betalen salaris ingehouden als voorzorgsmaatregel tegen eventuele boetes of sancties die aan de werkgever te laat zijn bereikent.
B40: Overige afspraken
B41: ▪ | C41: Werknemer heeft recht op 10,92% vakantiedagentoeslag
B42: ▪ | C42: 8,33% vakantietoeslag over de gewerkte uren;
B43: ▪ | C43: Opzegtermijn volgens CAO ABU;
B44: ▪ | C44: Opbouw feestdagen volgens CAO ABU;
B45: ▪ | C45: Pensioen volgens CAO ABU;
B46: ▪ | C46: Kort verzuim volgens CAO ABU;
B47: ▪ | C47: Werkgever betaalt volledig de wettelijke bijdrage ziektekosten (bijtelling werknemer);
B48: ▪ | C48: Werkgever houdt de overuren bij en betaalt uit tijdens vakantie tegen gewerkte uurtarief.
B50: Artikel 5: | D50: clausule ‘Vangnetter’
B51: 5.1. | C51: De werknemer die binnen 4 weken na het einde van het dienstverband ziek wordt, en op dat moment niet werkzaam is bij een andere werkgever of een WW-uitkering geniet, meldt zich onmiddellijk ziek bij werkgever conform de bij werkgever geldende regels omtrent ziekmeldingen;
B52: 5.2. | C52: De werknemer die ziek is op het moment dat hij uit dienst gaat en de werknemer die voldoet aan het bepaalde in lid 1 van dit artikel, dient:
...

Sheet KIWA
B2: VERKLARING VAN TERBESCHIKKINGSTELLING
B3: Wet wegvervoer goederen
B4: 2 | C4: 0 | D4: 2 | E4: 2 | F4: - | G4: 2 | H4: 8 | I4: 3 | J4: 4
F5: Nummer:
B7: Aangewezen instelling: | L7: =FillIn!H4 -> DeNeX Uitzendbureau B.V.
B8: Adres: | L8: =FillIn!H6 -> Gebroken Meeldijk 66, Unit 1.15
L9: =FillIn!H7&" "&FillIn!H8 -> 2991 VD Barendrecht
B10: Telefoon: | L10: =FillIn!H9 -> +31628813127
B12: Verklaart ter beschikking te hebben gesteld aan:
B13: ="Naam vergunninghouder: "&FillIn!H4 -> Naam vergunninghouder: DeNeX Uitzendbureau B.V.
B14: 3 | C14: 2 | D14: 5 | E14: 3 | F14: 0 | G14: . | H14: . | I14: . | J14: . | K14: .
E16: Codenummer NIWO:
C17: De chauffeur:
B18: Naam en voorletters: | L18: =FillIn!O4 -> Aslan, G.
B19: Geboren op: | L19: =FillIn!D8 -> 29310
B20: Wonende te: | L20: =FillIn!D5 -> Bikscotelaan 248 /2/2140 Borgerhout
B21: Volledig adres: | L21: =FillIn!D6&" "&FillIn!D7 -> 2140 An twerp
C23: en verklaart de op dit formulier vermelde gegevens naar waarheid te hebben verstrekt en een kopie
C24: van deze verklaring aan de hierboven vermelde bestuurder van een vrachtauto te hebben uitgereikt.
B26: Datum uitreiking chauffeur | L26: =VLOOKUP(FillIn!$D$4,Employee!$A$3:$T$37,10,false) -> 45979
B28: Datum aanvang terbeschikkingstelling: | L28: =L26 -> 45979
B30: Datum einde terbeschikkingstelling: | L30: =L26+211 -> 46190
B32: Plaats: Barendrecht
B35: Handtekening aangewezen instelling: | O35: Handtekening chauffeur:
B40: =FillIn!M5 -> de heer D.O. Ibryam | O40: =FillIn!M4 -> de heer G. Aslan
B54: N.B. De bestuurder van een motorrijtuig is verplicht bij beëindiging van de terbeschikkingstelling deze verklaring in te leveren bij degene die hem ter beschikking heeft gesteld.

Sheet Schalen25
A1: TLN - Functieloonschalen per 1 januari 2025(+4%)
A2: Loonschaal/ trede | D2: Bedragen per: | G2: Uurloon à:
D3: Week | E3: 4 weken | F3: Maand | G3: 1 | H3: 1.3 | I3: 1.5
A4: A 1 | B4: A | C4: 1 | D4: 562.4 | E4: 2249.6 | F4: 2446.44 | G4: 14.06 | H4: 18.28 | I4: 21.09
A5: A 2 | B5: A | C5: 2 | D5: 569.12 | E5: 2276.48 | F5: 2474.53 | G5: 14.23 | H5: 18.5 | I5: 21.35
A6: A 3 | B6: A | C6: 3 | D6: 591.88 | E6: 2367.52 | F6: 2573.49 | G6: 14.8 | H6: 19.24 | I6: 22.2
A7: A 4 | B7: A | C7: 4 | D7: 615.55 | E7: 2462.2 | F7: 2676.41 | G7: 15.39 | H7: 20.01 | I7: 23.09
A8: A 5 | B8: A | C8: 5 | D8: 640.17 | E8: 2560.68 | F8: 2783.46 | G8: 16 | H8: 20.8 | I8: 24
A9: A 6 | B9: A | C9: 6 | D9: 665.78 | E9: 2663.12 | F9: 2894.81 | G9: 16.64 | H9: 21.63 | I9: 24.96
A10: B 1 | B10: B | C10: 1 | D10: 576.08 | E10: 2304.32 | F10: 2504.8 | G10: 14.4 | H10: 18.72 | I10: 21.6
A11: B 2 | B11: B | C11: 2 | D11: 599.12 | E11: 2396.48 | F11: 2604.97 | G11: 14.98 | H11: 19.47 | I11: 22.47
A12: B 3 | B12: B | C12: 3 | D12: 623.08 | E12: 2492.32 | F12: 2709.15 | G12: 15.58 | H12: 20.25 | I12: 23.37
A13: B 4 | B13: B | C13: 4 | D13: 648 | E13: 2592 | F13: 2817.5 | G13: 16.2 | H13: 21.06 | I13: 24.3
A14: B 5 | B14: B | C14: 5 | D14: 673.92 | E14: 2695.68 | F14: 2930.2 | G14: 16.85 | H14: 21.91 | I14: 25.28
A15: B 6 | B15: B | C15: 6 | D15: 700.88 | E15: 2803.52 | F15: 3047.43 | G15: 17.52 | H15: 22.78 | I15: 26.28
... A61: H 10 | B61: H | C61: 10 | D61: 1111.22 | E61: 4444.88 | F61: 4831.58 | G61: 27.78 | H61: 36.11 | I61: 41.67

Sheet Vakantie
A2: 1 | B2: 0 | C2: 16 | D2: < 16 jaar | E2: 22 dagen
A3: 2 | B3: 17 | C3: 18 | D3: 17 en 18 jaar | E3: 23 dagen
A4: 3 | B4: 19 | C4: 39 | D4: 19 t/m 39 jaar | E4: 24 dagen
A5: 4 | B5: 40 | C5: 44 | D5: 40 t/m 44 jaar | E5: 24 dagen
A6: 5 | B6: 45 | C6: 49 | D6: 45 t/m 49 jaar | E6: 25 dagen
A7: 6 | B7: 50 | C7: 54 | D7: 50 t/m 54 jaar | E7: 26 dagen
A8: 7 | B8: 55 | C8: 59 | D8: 55 t/m 59 jaar | E8: 27 dagen
A9: 8 | B9: 60 | C9: 140 | D9: > 60 jaar | E9: 28 dagen
A13: <16 jaar | B13: 28 dagen
A14: 17 en 18 jaar | B14: 26 dagen
A15: 19 t/m 39 jaar | B15: 24 dagen
A16: 40 t/m 44 jaar | B16: 24 dagen
A17: 45 t/m 49 jaar | B17: 25 dagen
A18: 50 t/m 54 jaar | B18: 26 dagen
A19: 55 t/m 59 jaar | B19: 27 dagen
A20: >60 jaar | B20: 28 dagen

Sheet CRM
A1: Accountnaam | B1: Map | C1: Voorletters | D1: Verjardig | E1: BSN Nummer | F1: Postadres | G1: Factuur Plaats | H1: Factuur Postcode | I1: Primaire Telefoon | J1: KvKNummer | K1: IBAN Zakelijk | L1: BTW-ID | M1: Begroeting | N1: Primaire E-Mail | O1: Achternaam
A2: A. Iliev | B2: 1333 | C2: A.N. | D2: 34490 | E2: 694524268 | F2: Springersdiep 21 | G2: s-Gravenhage | H2: 2904ET | I2: +359882707869 | J2: 85495239 | K2: NL | L2: NL004103132B76 | M2: Hr. | N2: aleksandur91@gmail.com | O2: Iliev
A3: A.A. Kazakov | B3: 1074 | C3: A.A. | D3: 28527 | E3: 673253570 | F3: Loosduinseweg 867 | G3: s-Gravenhage | H3: 2571AV | I3: 0685411440 | J3: 82225443 | K3: NL | L3: NL003657916B47 | M3: Hr. | N3: kazakovasen5@gmail.com | O3: Kazakov
A4: A.B. Mitev | B4: 923 | C4: A.B. | D4: 27306 | E4: 454395681 | F4: Dautzenbergstraat 21 | G4: s-Gravenhage | H4: 2523KB | I4: 0684083090 | J4: 76889084 | K4: NL | L4: NL003142606B73 | M4: Hr. | N4: atanas.borisov.mitev@gmail.com | O4: Mitev
A5: A.N.R. Logistics - gemaild - Achterstand BORA | B5: 1583 | C5: V.I. | D5: 32036 | E5: 608580570 | F5: Thijssestraat 215 | G5: s-Gravenhage | H5: 2521ZG | I5: 0624950200 | J5: 92756778 | K5: NL | L5: NL004974407B81 | M5: Hr. | N5: johnnyblaze2fu@gmail.com | O5: Ryazantsev
A6: A.R.S. 89 | B6: 672 | C6: A.R. | D6: 32662 | E6: 395720655 | F6: Jan van der Heijdenstraat 90 | G6: s-Gravenhage | H6: 2522ES | I6: 0638663285 | J6: 73604445 | K6: NL | L6: NL002478396B47 | M6: Hr. | N6: aliosman123987@abv.bg | O6: Shefket
A7: A1 Maatwerk (Tolidar Design VOF) | B7: 698 | C7: A.V. | D7: 29473 | E7: 565284769 | F7: B. Thoenplantsoen 26 | G7: s-Gravenhage | H7: 2552JK | I7: 0612374803 | J7: 73835110 | K7: NL61INGB0006019712 | L7: NL859680484B01 | M7: Hr. | N7: tolidardesign@gmail.com | O7: Volyanyuk
A8: ABZ Bouw | B8: 1680 | C8: Z.D. | D8: 31064 | E8: 398790942 | F8: Van Merlenstraat 58 | G8: s-Gravenhage | H8: 2518TG | I8: 0653958410 | J8: 89949382 | K8: NL | L8: NL004774766B22 | M8: Hr. | N8: zdravkokovachev09@gmail.com | O8: Kovachev
A9: ADI 2018 VOF | B9: 513 | C9: A.S. | D9: 29558 | E9: 545568912 | F9: Jan van der Heydenstraat 4 | G9: s-Gravenhage | H9: 2522EP | I9: 0645025254 | J9: 70947279 | K9: NL | L9: NL858521544B01 | M9: Hr. | N9: anio198@abv.bg | O9: Shopov
A10: AdiMar Bouw | B10: 1541 | C10: A. | D10: 37883 | E10: 664233387 | F10: Obrecht 46 | G10: s-Gravenhage | H10: 2681JM | I10: 0687718709 | J10: 91673569 | K10: NL | L10: NL004907918B89 | M10: Hr. | N10: adrianmarcinczyk5@gmail.com | O10: Marcinczyk
A11: Adix Bouw | B11: 1008 | C11: P.A. | D11: 31271 | E11: 360984940 | F11: Hoefkade 491A | G11: s-Gravenhage | H11: 2525LA | I11: 0684809083 | J11: 78629713 | K11: NL | L11: NL003357920B16 | M11: Hr. | N11: peshoasd85@gmail.com | O11: Mitev
A12: AFM Bouw | B12: 9 | C12: M.Y. | D12: 26169 | E12: 425616083 | F12: Van Diesenstraat 255 | G12: s-Gravenhage | H12: 2521EH | I12: 0620479796 | J12: 56661371 | K12: NL | L12: NL002482305B77 | M12: Hr. | N12: amfbouw1@gmail.com | O12: Filipov
A13: Agora Boekhouding - KOR per 01-04-2023 | B13: 902 | C13: H.A. | D13: 25518 | E13: 255501377 | F13: Burgemeester Elsenlaan 329 | G13: s-Gravenhage | H13: 2282MZ | I13: 0611584401 | J13: 59682132 | K13: NL | L13: NL002447245B76 | M13: Mw. | N13: infoagora69@gmail.com | O13: Tyankova
... A50: Asya Asenova | B50: 1573 | C50: A.H. | D50: 37263 | E50: 691702512 | F50: Beeklaan 215 | G50: s-Gravenhage | H50: 2562AE | I50: +359877177810 | J50: 92556957 | K50: NL | L50: NL004960785B71 | M50: Hr. | N50: asenovaasa566@gmail.com | O50: Asenova
A51: Atka | B51: 1001 | C51: A.A. | D51: 27644 | E51: 660264705 | F51: Paets van Troostwijkstr 53 | G51: s-Gravenhage | H51: 2522DL | I51: 0683871250 | J51: 52955397 | K51: NL | M51: Hr. | N51: atka07@hotmail.com | O51: Sadula
A52: Axentis | B52: 901 | C52: E.J. | D52: 22107 | E52: 126248175 | F52: Steenplaetsstraat 6 | G52: s-Gravenhage | H52: 2288AA | I52: 0707505651 | J52: 55962734 | K52: NL | L52: NL001565172B59 | M52: Hr. | N52: rangelov.e@gmail.com | O52: Rangelov
